Workbook

Sheet Read Me
B2: Borssele 1 & 2 Project Finance Debt Model
B5: Tabs
B6: Assumptions: all inputs (blue). Change a value and the model recalculates.
B7: Debt Sizing: sizes the facility off the lowest of a DSCR-sculpted test, a leverage cap, and an LLCR test.
B8: Cash Flow & Waterfall: annual model, years 0-25: production through equity distributions.
B9: Stress Tests: P90 production, price shock, cost overrun, combined stress.
B10: Dashboard: key outputs and the Gemini benchmark comparison.
B12: Debt sizing methodology (avoids circularity)
B13: Debt is sized off the lowest of three tests:
B14: 1) DSCR-sculpted capacity: initial balance = PV of the CFADS/DSCR-target debt service
B15: stream, discounted at the loan interest rate (a closed-form NPV, no circular
B16: iteration needed).
... B36: Project 1's ex-ante lens.

Sheet Assumptions
A1: Assumptions
A4: Parameter | B4: Value | C4: Unit | D4: Source / note
A5: Physical & production
A6: Capacity | B6: 752 | C6: MW | D6: Orsted (final)
A7: Capacity factor (P50) | B7: 0.5 | C7: fraction | D7: CREG 2016
A8: Annual degradation | B8: 0 | C8: fraction | D8: As Project 1
A9: P90 uncertainty (of P50) | B9: 0.1 | C9: fraction | D9: Market convention, wind EYA (~8-12%)
A10: Capacity factor (P90) | B10: =_xlfn.NORM.INV(0.1,B7,B7*B9) -> 0.43592242 | C10: fraction | D10: NORM.INV(0.10, P50, P50 x uncertainty)
A11: CAPEX & decommissioning
A12: CAPEX total (EIB) | B12: 1491 | C12: EUR m | D12: EIB 2020
A13: CAPEX total | B13: =B12*1000000 -> 1491000000 | C13: EUR | D13: m x 1,000,000
A14: Decommissioning cost | B14: 42 | C14: EUR m | D14: CREG 2016
A15: Cost overrun (stress) | B15: 0.2 | C15: fraction | D15: Stress test input
A16: OPEX
A17: OPEX variable | B17: 9.59 | C17: EUR/MWh | D17: CREG 2016
A18: OPEX fixed | B18: 40350 | C18: EUR/MW/yr | D18: CREG 2016
A19: OPEX inflation | B19: 0.02 | C19: fraction/yr | D19: Assumption
A20: Revenue / SDE+ (ex-ante lens)
A21: Tender amount | B21: 72.7 | C21: EUR/MWh | D21: CREG / Orsted / EZ
A22: Floor (base electricity price) | B22: 29 | C22: EUR/MWh | D22: RVO
A23: Subsidy period | B23: 15 | C23: years | D23: Court of Audit / RVO
A24: Market price (ex-ante) | B24: 30 | C24: EUR/MWh | D24: CREG 2016
A25: Price shock (stress) | B25: -0.2 | C25: fraction | D25: Stress test input
A26: Original financing (2016)
A27: EUR 15Y swap rate | B27: 0.00579 | C27: fraction | D27: ADB Treasury, 31-Aug-2016
A28: Margin | B28: 0.022 | C28: fraction | D28: Green Giraffe (<225bp for 2016)
A29: All-in interest rate | B29: =B27+B28 -> 0.02779 | C29: fraction | D29: swap + margin
A30: Leverage cap | B30: 0.7 | C30: fraction of CAPEX | D30: LOFOTR (70-80% range); Gemini ~70%
A31: Debt tenor | B31: 15 | C31: years | D31: Green Giraffe 2016; matches subsidy period
A32: DSCR sculpting target | B32: 1.3 | C32: x | D32: LOFOTR / Fitch (contracted)
A33: DSCR historic covenant | B33: 1.1 | C33: x | D33: LOFOTR term sheet
A34: DSCR forward covenant | B34: 1.15 | C34: x | D34: LOFOTR term sheet
A35: Distribution lock-up DSCR | B35: 1.2 | C35: x | D35: LOFOTR term sheet (1.20-1.25x)
A36: LLCR minimum | B36: 1.4 | C36: x | D36: LOFOTR / SunRaise
A37: LLCR discount rate (real) | B37: 0.07 | C37: fraction | D37: SunRaise (6-8% real)
A38: DSRA target | B38: 6 | C38: months debt service | D38: Forvis Mazars / Financial Edge / LOFOTR
A39: Tax
A40: CIT low-bracket threshold | B40: 200000 | C40: EUR | D40: Belastingdienst 2026
A41: CIT low-bracket rate | B41: 0.19 | C41: fraction | D41: Belastingdienst 2026
A42: CIT high-bracket rate | B42: 0.258 | C42: fraction | D42: Belastingdienst 2026
...

Sheet Debt Sizing
A1: Debt Sizing
A4: Metric | B4: Value | C4: Note
A5: CFADS for sizing (excl. interest tax shield)
A6: Gross annual production (P50) | B6: =Assumptions!$B$6*Assumptions!$B$7*8760 -> 3293760
A7: Depreciation (per year) | B7: =Assumptions!$B$13/Assumptions!$B$59 -> 59640000
A8: Sizing-basis 15-year debt service (CFADS / DSCR target)
A9: Operational year | B9: 1 | C9: 2 | D9: 3 | E9: 4 | F9: 5 | G9: 6 | H9: 7 | I9: 8 | J9: 9 | K9: 10 | L9: 11 | M9: 12 | N9: 13 | O9: 14 | P9: 15
A10: Production (MWh) | B10: =$B$6*(1-Assumptions!$B$8)^(B$9-1) -> 3293760 | C10: =$B$6*(1-Assumptions!$B$8)^(C$9-1) -> 3293760 | D10: =$B$6*(1-Assumptions!$B$8)^(D$9-1) -> 3293760 | E10: =$B$6*(1-Assumptions!$B$8)^(E$9-1) -> 3293760 | F10: =$B$6*(1-Assumptions!$B$8)^(F$9-1) -> 3293760 | G10: =$B$6*(1-Assumptions!$B$8)^(G$9-1) -> 3293760 | H10: =$B$6*(1-Assumptions!$B$8)^(H$9-1) -> 3293760 | I10: =$B$6*(1-Assumptions!$B$8)^(I$9-1) -> 3293760 | ... P10: =$B$6*(1-Assumptions!$B$8)^(P$9-1) -> 3293760
A11: Revenue (EUR) [tender-capped] | B11: =B$10*Assumptions!$B$21 -> 239456352 | C11: =C$10*Assumptions!$B$21 -> 239456352 | D11: =D$10*Assumptions!$B$21 -> 239456352 | E11: =E$10*Assumptions!$B$21 -> 239456352 | F11: =F$10*Assumptions!$B$21 -> 239456352 | G11: =G$10*Assumptions!$B$21 -> 239456352 | H11: =H$10*Assumptions!$B$21 -> 239456352 | I11: =I$10*Assumptions!$B$21 -> 239456352 | ... P11: =P$10*Assumptions!$B$21 -> 239456352
A12: OPEX (EUR) | B12: =(Assumptions!$B$17*(1+Assumptions!$B$19)^(B$9-1)*B$10)+(Assumptions!$B$18*(1+Assumptions!$B$19)^(B$9-1)*Assumptions!$B$6) -> 61930358 | C12: =(Assumptions!$B$17*(1+Assumptions!$B$19)^(C$9-1)*C$10)+(Assumptions!$B$18*(1+Assumptions!$B$19)^(C$9-1)*Assumptions!$B$6) -> 63168966 | D12: =(Assumptions!$B$17*(1+Assumptions!$B$19)^(D$9-1)*D$10)+(Assumptions!$B$18*(1+Assumptions!$B$19)^(D$9-1)*Assumptions!$B$6) -> 64432345 | E12: =(Assumptions!$B$17*(1+Assumptions!$B$19)^(E$9-1)*E$10)+(Assumptions!$B$18*(1+Assumptions!$B$19)^(E$9-1)*Assumptions!$B$6) -> 65720992 | F12: =(Assumptions!$B$17*(1+Assumptions!$B$19)^(F$9-1)*F$10)+(Assumptions!$B$18*(1+Assumptions!$B$19)^(F$9-1)*Assumptions!$B$6) -> 67035412 | G12: =(Assumptions!$B$17*(1+Assumptions!$B$19)^(G$9-1)*G$10)+(Assumptions!$B$18*(1+Assumptions!$B$19)^(G$9-1)*Assumptions!$B$6) -> 68376120 | H12: =(Assumptions!$B$17*(1+Assumptions!$B$19)^(H$9-1)*H$10)+(Assumptions!$B$18*(1+Assumptions!$B$19)^(H$9-1)*Assumptions!$B$6) -> 69743642 | I12: =(Assumptions!$B$17*(1+Assumptions!$B$19)^(I$9-1)*I$10)+(Assumptions!$B$18*(1+Assumptions!$B$19)^(I$9-1)*Assumptions!$B$6) -> 71138515 | ... P12: =(Assumptions!$B$17*(1+Assumptions!$B$19)^(P$9-1)*P$10)+(Assumptions!$B$18*(1+Assumptions!$B$19)^(P$9-1)*Assumptions!$B$6) -> 81715793
A13: EBITDA (EUR) | B13: =B$11-B$12 -> 1.7752599e+08 | C13: =C$11-C$12 -> 1.7628739e+08 | D13: =D$11-D$12 -> 1.7502401e+08 | E13: =E$11-E$12 -> 1.7373536e+08 | F13: =F$11-F$12 -> 1.7242094e+08 | G13: =G$11-G$12 -> 1.7108023e+08 | H13: =H$11-H$12 -> 1.6971271e+08 | I13: =I$11-I$12 -> 1.6831784e+08 | ... P13: =P$11-P$12 -> 1.5774056e+08
A14: EBIT (EUR, pre-interest) | B14: =B$13-$B$7 -> 1.1788599e+08 | C14: =C$13-$B$7 -> 1.1664739e+08 | D14: =D$13-$B$7 -> 1.1538401e+08 | E14: =E$13-$B$7 -> 1.1409536e+08 | F14: =F$13-$B$7 -> 1.1278094e+08 | G14: =G$13-$B$7 -> 1.1144023e+08 | H14: =H$13-$B$7 -> 1.1007271e+08 | I14: =I$13-$B$7 -> 1.0867784e+08 | ... P14: =P$13-$B$7 -> 98100559
A15: Sizing tax (excl. interest shield) | B15: =IF(B$14<=0,0,IF(B$14<=Assumptions!$B$40,B$14*Assumptions!$B$41,Assumptions!$B$40*Assumptions!$B$41+(B$14-Assumptions!$B$40)*Assumptions!$B$42)) -> 30400986 | C15: =IF(C$14<=0,0,IF(C$14<=Assumptions!$B$40,C$14*Assumptions!$B$41,Assumptions!$B$40*Assumptions!$B$41+(C$14-Assumptions!$B$40)*Assumptions!$B$42)) -> 30081426 | D15: =IF(D$14<=0,0,IF(D$14<=Assumptions!$B$40,D$14*Assumptions!$B$41,Assumptions!$B$40*Assumptions!$B$41+(D$14-Assumptions!$B$40)*Assumptions!$B$42)) -> 29755474 | E15: =IF(E$14<=0,0,IF(E$14<=Assumptions!$B$40,E$14*Assumptions!$B$41,Assumptions!$B$40*Assumptions!$B$41+(E$14-Assumptions!$B$40)*Assumptions!$B$42)) -> 29423003 | F15: =IF(F$14<=0,0,IF(F$14<=Assumptions!$B$40,F$14*Assumptions!$B$41,Assumptions!$B$40*Assumptions!$B$41+(F$14-Assumptions!$B$40)*Assumptions!$B$42)) -> 29083883 | G15: =IF(G$14<=0,0,IF(G$14<=Assumptions!$B$40,G$14*Assumptions!$B$41,Assumptions!$B$40*Assumptions!$B$41+(G$14-Assumptions!$B$40)*Assumptions!$B$42)) -> 28737980 | H15: =IF(H$14<=0,0,IF(H$14<=Assumptions!$B$40,H$14*Assumptions!$B$41,Assumptions!$B$40*Assumptions!$B$41+(H$14-Assumptions!$B$40)*Assumptions!$B$42)) -> 28385159 | I15: =IF(I$14<=0,0,IF(I$14<=Assumptions!$B$40,I$14*Assumptions!$B$41,Assumptions!$B$40*Assumptions!$B$41+(I$14-Assumptions!$B$40)*Assumptions!$B$42)) -> 28025282 | ... P15: =IF(P$14<=0,0,IF(P$14<=Assumptions!$B$40,P$14*Assumptions!$B$41,Assumptions!$B$40*Assumptions!$B$41+(P$14-Assumptions!$B$40)*Assumptions!$B$42)) -> 25296344
A16: CFADS (sizing basis) | B16: =B$13-B$15 -> 1.4712501e+08 | C16: =C$13-C$15 -> 1.4620596e+08 | D16: =D$13-D$15 -> 1.4526853e+08 | E16: =E$13-E$15 -> 1.4431236e+08 | F16: =F$13-F$15 -> 1.4333706e+08 | G16: =G$13-G$15 -> 1.4234225e+08 | H16: =H$13-H$15 -> 1.4132755e+08 | I16: =I$13-I$15 -> 1.4029255e+08 | ... P16: =P$13-P$15 -> 1.3244422e+08
A17: Sizing debt service (CFADS/target) | B17: =B$16/Assumptions!$B$32 -> 1.1317308e+08 | C17: =C$16/Assumptions!$B$32 -> 1.1246612e+08 | D17: =D$16/Assumptions!$B$32 -> 1.1174503e+08 | E17: =E$16/Assumptions!$B$32 -> 1.1100951e+08 | F17: =F$16/Assumptions!$B$32 -> 1.1025928e+08 | G17: =G$16/Assumptions!$B$32 -> 1.0949404e+08 | H17: =H$16/Assumptions!$B$32 -> 1.087135e+08 | I17: =I$16/Assumptions!$B$32 -> 1.0791735e+08 | ... P17: =P$16/Assumptions!$B$32 -> 1.0188017e+08
A19: Sizing outcome
A20: DSCR-sculpted debt capacity (EUR) | B20: =NPV(Assumptions!$B$29,B$17:P$17) -> 1.3123208e+09 | C20: PV of sculpted debt service, discounted at the loan rate
A21: Leverage cap (EUR) | B21: =Assumptions!$B$30*Assumptions!$B$13 -> 1.0437e+09 | C21: 70% of total project cost
A22: LLCR-implied debt capacity (EUR) | B22: =NPV(Assumptions!$B$37,B$16:P$16)/Assumptions!$B$36 -> 9.1985741e+08 | C22: PV of sizing CFADS at the LLCR discount rate, / LLCR minimum
A23: Actual initial debt balance (EUR) | B23: =MIN(B20,B21,B22) -> 9.1985741e+08 | C23: Lower of the three tests
A24: Scale factor (actual / DSCR-sculpted) | B24: =B23/B20 -> 0.70093945
A25: Implied realised DSCR (base case, flat) | B25: =Assumptions!$B$32/B24 -> 1.8546538
A26: Binding constraint | B26: =IF(B23=B20,"DSCR sculpting",IF(B23=B21,"Leverage cap","LLCR")) -> LLCR
A28: Actual (scaled) 15-year debt service
A29: Actual debt service (EUR) | B29: =B$17*$B$24 -> 79327478 | C29: =C$17*$B$24 -> 78831943 | D29: =D$17*$B$24 -> 78326497 | E29: =E$17*$B$24 -> 77810942 | F29: =F$17*$B$24 -> 77285076 | G29: =G$17*$B$24 -> 76748693 | H29: =H$17*$B$24 -> 76201581 | I29: =I$17*$B$24 -> 75643528 | ... P29: =P$17*$B$24 -> 71411827
A31: LLCR at financial close (actual debt) | B31: =NPV(Assumptions!$B$37,B$16:P$16)/B23 -> 1.4

Sheet Cash Flow & Waterfall
A1: Cash Flow & Waterfall
A4: Calendar year | C4: =Assumptions!$B$58-1 -> 2020 | D4: =Assumptions!$B$58+0 -> 2021 | E4: =Assumptions!$B$58+1 -> 2022 | F4: =Assumptions!$B$58+2 -> 2023 | G4: =Assumptions!$B$58+3 -> 2024 | H4: =Assumptions!$B$58+4 -> 2025 | I4: =Assumptions!$B$58+5 -> 2026 | J4: =Assumptions!$B$58+6 -> 2027 | K4: =Assumptions!$B$58+7 -> 2028 | L4: =Assumptions!$B$58+8 -> 2029 | M4: =Assumptions!$B$58+9 -> 2030 | N4: =Assumptions!$B$58+10 -> 2031 | O4: =Assumptions!$B$58+11 -> 2032 | P4: =Assumptions!$B$58+12 -> 2033 | Q4: =Assumptions!$B$58+13 -> 2034 | R4: =Assumptions!$B$58+14 -> 2035 | S4: =Assumptions!$B$58+15 -> 2036 | T4: =Assumptions!$B$58+16 -> 2037 | U4: =Assumptions!$B$58+17 -> 2038 | V4: =Assumptions!$B$58+18 -> 2039 | W4: =Assumptions!$B$58+19 -> 2040 | X4: =Assumptions!$B$58+20 -> 2041 | Y4: =Assumptions!$B$58+21 -> 2042 | Z4: =Assumptions!$B$58+22 -> 2043 | AA4: =Assumptions!$B$58+23 -> 2044 | AB4: =Assumptions!$B$58+24 -> 2045
A5: Operational year | C5: 0 | D5: 1 | E5: 2 | F5: 3 | G5: 4 | H5: 5 | I5: 6 | J5: 7 | K5: 8 | L5: 9 | M5: 10 | N5: 11 | O5: 12 | P5: 13 | Q5: 14 | R5: 15 | S5: 16 | T5: 17 | U5: 18 | V5: 19 | W5: 20 | X5: 21 | Y5: 22 | Z5: 23 | AA5: 24 | AB5: 25
A8: PRODUCTION
A9: Degradation factor | C9: 0 | D9: =(1-Assumptions!$B$8)^(D$5-1) -> 1 | E9: =(1-Assumptions!$B$8)^(E$5-1) -> 1 | F9: =(1-Assumptions!$B$8)^(F$5-1) -> 1 | G9: =(1-Assumptions!$B$8)^(G$5-1) -> 1 | H9: =(1-Assumptions!$B$8)^(H$5-1) -> 1 | I9: =(1-Assumptions!$B$8)^(I$5-1) -> 1 | J9: =(1-Assumptions!$B$8)^(J$5-1) -> 1 | K9: =(1-Assumptions!$B$8)^(K$5-1) -> 1 | ... AB9: =(1-Assumptions!$B$8)^(AB$5-1) -> 1
A10: Net production (MWh) | C10: 0 | D10: =Assumptions!$B$6*Assumptions!$B$7*8760*D$9 -> 3293760 | E10: =Assumptions!$B$6*Assumptions!$B$7*8760*E$9 -> 3293760 | F10: =Assumptions!$B$6*Assumptions!$B$7*8760*F$9 -> 3293760 | G10: =Assumptions!$B$6*Assumptions!$B$7*8760*G$9 -> 3293760 | H10: =Assumptions!$B$6*Assumptions!$B$7*8760*H$9 -> 3293760 | I10: =Assumptions!$B$6*Assumptions!$B$7*8760*I$9 -> 3293760 | J10: =Assumptions!$B$6*Assumptions!$B$7*8760*J$9 -> 3293760 | K10: =Assumptions!$B$6*Assumptions!$B$7*8760*K$9 -> 3293760 | ... AB10: =Assumptions!$B$6*Assumptions!$B$7*8760*AB$9 -> 3293760
A11: REVENUE (ex-ante lens)
A12: Market price (EUR/MWh) | C12: 0 | D12: =Assumptions!$B$24 -> 30 | E12: =Assumptions!$B$24 -> 30 | F12: =Assumptions!$B$24 -> 30 | G12: =Assumptions!$B$24 -> 30 | H12: =Assumptions!$B$24 -> 30 | I12: =Assumptions!$B$24 -> 30 | J12: =Assumptions!$B$24 -> 30 | K12: =Assumptions!$B$24 -> 30 | ... AB12: =Assumptions!$B$24 -> 30
A13: Subsidy (EUR/MWh) | C13: 0 | D13: =IF(D$5<=Assumptions!$B$23,MAX(0,Assumptions!$B$21-MAX(D$12,Assumptions!$B$22)),0) -> 42.7 | E13: =IF(E$5<=Assumptions!$B$23,MAX(0,Assumptions!$B$21-MAX(E$12,Assumptions!$B$22)),0) -> 42.7 | F13: =IF(F$5<=Assumptions!$B$23,MAX(0,Assumptions!$B$21-MAX(F$12,Assumptions!$B$22)),0) -> 42.7 | G13: =IF(G$5<=Assumptions!$B$23,MAX(0,Assumptions!$B$21-MAX(G$12,Assumptions!$B$22)),0) -> 42.7 | H13: =IF(H$5<=Assumptions!$B$23,MAX(0,Assumptions!$B$21-MAX(H$12,Assumptions!$B$22)),0) -> 42.7 | I13: =IF(I$5<=Assumptions!$B$23,MAX(0,Assumptions!$B$21-MAX(I$12,Assumptions!$B$22)),0) -> 42.7 | J13: =IF(J$5<=Assumptions!$B$23,MAX(0,Assumptions!$B$21-MAX(J$12,Assumptions!$B$22)),0) -> 42.7 | K13: =IF(K$5<=Assumptions!$B$23,MAX(0,Assumptions!$B$21-MAX(K$12,Assumptions!$B$22)),0) -> 42.7 | ... R13: =IF(R$5<=Assumptions!$B$23,MAX(0,Assumptions!$B$21-MAX(R$12,Assumptions!$B$22)),0) -> 42.7 | S13: 0 | T13: 0 | U13: 0 | V13: 0 | W13: 0 | X13: 0 | Y13: 0 | Z13: 0 | AA13: 0 | AB13: 0
A14: Total price (EUR/MWh) | C14: 0 | D14: =D$12+D$13 -> 72.7 | E14: =E$12+E$13 -> 72.7 | F14: =F$12+F$13 -> 72.7 | G14: =G$12+G$13 -> 72.7 | H14: =H$12+H$13 -> 72.7 | I14: =I$12+I$13 -> 72.7 | J14: =J$12+J$13 -> 72.7 | K14: =K$12+K$13 -> 72.7 | ... AB14: =AB$12+AB$13 -> 30
A15: Total revenue (EUR) | C15: 0 | D15: =D$10*D$14 -> 239456352 | E15: =E$10*E$14 -> 239456352 | F15: =F$10*F$14 -> 239456352 | G15: =G$10*G$14 -> 239456352 | H15: =H$10*H$14 -> 239456352 | I15: =I$10*I$14 -> 239456352 | J15: =J$10*J$14 -> 239456352 | K15: =K$10*K$14 -> 239456352 | ... AB15: =AB$10*AB$14 -> 98812800
A16: OPEX
A17: OPEX variable (EUR) | C17: 0 | D17: =Assumptions!$B$17*(1+Assumptions!$B$19)^(D$5-1)*D$10 -> 31587158 | E17: =Assumptions!$B$17*(1+Assumptions!$B$19)^(E$5-1)*E$10 -> 32218902 | F17: =Assumptions!$B$17*(1+Assumptions!$B$19)^(F$5-1)*F$10 -> 32863280 | G17: =Assumptions!$B$17*(1+Assumptions!$B$19)^(G$5-1)*G$10 -> 33520545 | H17: =Assumptions!$B$17*(1+Assumptions!$B$19)^(H$5-1)*H$10 -> 34190956 | I17: =Assumptions!$B$17*(1+Assumptions!$B$19)^(I$5-1)*I$10 -> 34874775 | J17: =Assumptions!$B$17*(1+Assumptions!$B$19)^(J$5-1)*J$10 -> 35572271 | K17: =Assumptions!$B$17*(1+Assumptions!$B$19)^(K$5-1)*K$10 -> 36283716 | ... AB17: =Assumptions!$B$17*(1+Assumptions!$B$19)^(AB$5-1)*AB$10 -> 50805962
A18: OPEX fixed (EUR) | C18: 0 | D18: =Assumptions!$B$18*(1+Assumptions!$B$19)^(D$5-1)*Assumptions!$B$6 -> 30343200 | E18: =Assumptions!$B$18*(1+Assumptions!$B$19)^(E$5-1)*Assumptions!$B$6 -> 30950064 | F18: =Assumptions!$B$18*(1+Assumptions!$B$19)^(F$5-1)*Assumptions!$B$6 -> 31569065 | G18: =Assumptions!$B$18*(1+Assumptions!$B$19)^(G$5-1)*Assumptions!$B$6 -> 32200447 | H18: =Assumptions!$B$18*(1+Assumptions!$B$19)^(H$5-1)*Assumptions!$B$6 -> 32844456 | I18: =Assumptions!$B$18*(1+Assumptions!$B$19)^(I$5-1)*Assumptions!$B$6 -> 33501345 | J18: =Assumptions!$B$18*(1+Assumptions!$B$19)^(J$5-1)*Assumptions!$B$6 -> 34171372 | K18: =Assumptions!$B$18*(1+Assumptions!$B$19)^(K$5-1)*Assumptions!$B$6 -> 34854799 | ... AB18: =Assumptions!$B$18*(1+Assumptions!$B$19)^(AB$5-1)*Assumptions!$B$6 -> 48805133
A19: Total OPEX (EUR) | C19: 0 | D19: =D$17+D$18 -> 61930358 | E19: =E$17+E$18 -> 63168966 | F19: =F$17+F$18 -> 64432345 | G19: =G$17+G$18 -> 65720992 | H19: =H$17+H$18 -> 67035412 | I19: =I$17+I$18 -> 68376120 | J19: =J$17+J$18 -> 69743642 | K19: =K$17+K$18 -> 71138515 | ... AB19: =AB$17+AB$18 -> 99611095
A20: EBITDA & DEPRECIATION
A21: EBITDA (EUR) | C21: 0 | D21: =D$15-D$19 -> 1.7752599e+08 | E21: =E$15-E$19 -> 1.7628739e+08 | F21: =F$15-F$19 -> 1.7502401e+08 | G21: =G$15-G$19 -> 1.7373536e+08 | H21: =H$15-H$19 -> 1.7242094e+08 | I21: =I$15-I$19 -> 1.7108023e+08 | J21: =J$15-J$19 -> 1.6971271e+08 | K21: =K$15-K$19 -> 1.6831784e+08 | ... AB21: =AB$15-AB$19 -> -798295.32
A22: Depreciation (EUR) | C22: 0 | D22: =Assumptions!$B$13/Assumptions!$B$59 -> 59640000 | E22: =Assumptions!$B$13/Assumptions!$B$59 -> 59640000 | F22: =Assumptions!$B$13/Assumptions!$B$59 -> 59640000 | G22: =Assumptions!$B$13/Assumptions!$B$59 -> 59640000 | H22: =Assumptions!$B$13/Assumptions!$B$59 -> 59640000 | I22: =Assumptions!$B$13/Assumptions!$B$59 -> 59640000 | J22: =Assumptions!$B$13/Assumptions!$B$59 -> 59640000 | K22: =Assumptions!$B$13/Assumptions!$B$59 -> 59640000 | ... AB22: =Assumptions!$B$13/Assumptions!$B$59 -> 59640000
A23: DEBT SCHEDULE (years 1-15 only)
A24: Opening balance (EUR) | C24: 0 | D24: ='Debt Sizing'!$B$23 -> 9.1985741e+08 | E24: =D$28 -> 8.6609276e+08 | F24: =E$28 -> 8.1132954e+08 | G24: =F$28 -> 7.5554989e+08 | H24: =G$28 -> 6.9873568e+08 | I24: =H$28 -> 6.4086847e+08 | J24: =I$28 -> 5.8192951e+08 | K24: =J$28 -> 5.2189975e+08 | L24: =K$28 -> 4.6075982e+08 | ... R24: =Q$28 -> 69480952 | S24: 0 | T24: 0 | U24: 0 | V24: 0 | W24: 0 | X24: 0 | Y24: 0 | Z24: 0 | AA24: 0 | AB24: 0
A25: Interest expense (EUR) | C25: 0 | D25: =D$24*Assumptions!$B$29 -> 25562837 | E25: =E$24*Assumptions!$B$29 -> 24068718 | F25: =F$24*Assumptions!$B$29 -> 22546848 | G25: =G$24*Assumptions!$B$29 -> 20996731 | H25: =H$24*Assumptions!$B$29 -> 19417865 | I25: =I$24*Assumptions!$B$29 -> 17809735 | J25: =J$24*Assumptions!$B$29 -> 16171821 | K25: =K$24*Assumptions!$B$29 -> 14503594 | ... AB25: =AB$24*Assumptions!$B$29 -> 0
A26: Debt service, total (EUR) | C26: 0 | D26: ='Debt Sizing'!$B$29 -> 79327478 | E26: ='Debt Sizing'!$C$29 -> 78831943 | F26: ='Debt Sizing'!$D$29 -> 78326497 | G26: ='Debt Sizing'!$E$29 -> 77810942 | H26: ='Debt Sizing'!$F$29 -> 77285076 | I26: ='Debt Sizing'!$G$29 -> 76748693 | J26: ='Debt Sizing'!$H$29 -> 76201581 | K26: ='Debt Sizing'!$I$29 -> 75643528 | L26: ='Debt Sizing'!$J$29 -> 75074314 | M26: ='Debt Sizing'!$K$29 -> 74493715 | N26: ='Debt Sizing'!$L$29 -> 73901505 | O26: ='Debt Sizing'!$M$29 -> 73297450 | P26: ='Debt Sizing'!$N$29 -> 72681314 | Q26: ='Debt Sizing'!$O$29 -> 72052855 | R26: ='Debt Sizing'!$P$29 -> 71411827 | S26: 0 | T26: 0 | U26: 0 | V26: 0 | W26: 0 | X26: 0 | Y26: 0 | Z26: 0 | AA26: 0 | AB26: 0
A27: Principal repayment (EUR) | C27: 0 | D27: =D$26-D$25 -> 53764641 | E27: =E$26-E$25 -> 54763225 | F27: =F$26-F$25 -> 55779649 | G27: =G$26-G$25 -> 56814211 | H27: =H$26-H$25 -> 57867211 | I27: =I$26-I$25 -> 58938958 | J27: =J$26-J$25 -> 60029760 | K27: =K$26-K$25 -> 61139934 | ... AB27: =AB$26-AB$25 -> 0
A28: Closing balance (EUR) | C28: 0 | D28: =MAX(0,D$24-D$27) -> 8.6609276e+08 | E28: =MAX(0,E$24-E$27) -> 8.1132954e+08 | F28: =MAX(0,F$24-F$27) -> 7.5554989e+08 | G28: =MAX(0,G$24-G$27) -> 6.9873568e+08 | H28: =MAX(0,H$24-H$27) -> 6.4086847e+08 | I28: =MAX(0,I$24-I$27) -> 5.8192951e+08 | J28: =MAX(0,J$24-J$27) -> 5.2189975e+08 | K28: =MAX(0,K$24-K$27) -> 4.6075982e+08 | ... AB28: =MAX(0,AB$24-AB$27) -> 0
A29: TAX (actual, incl. interest shield & ATAD cap)
A30: ATAD rate applicable | C30: 0 | D30: =IF(D$4<2022,Assumptions!$B$44,IF(D$4<2025,Assumptions!$B$45,Assumptions!$B$46)) -> 0.3 | E30: =IF(E$4<2022,Assumptions!$B$44,IF(E$4<2025,Assumptions!$B$45,Assumptions!$B$46)) -> 0.2 | F30: =IF(F$4<2022,Assumptions!$B$44,IF(F$4<2025,Assumptions!$B$45,Assumptions!$B$46)) -> 0.2 | G30: =IF(G$4<2022,Assumptions!$B$44,IF(G$4<2025,Assumptions!$B$45,Assumptions!$B$46)) -> 0.2 | H30: =IF(H$4<2022,Assumptions!$B$44,IF(H$4<2025,Assumptions!$B$45,Assumptions!$B$46)) -> 0.245 | I30: =IF(I$4<2022,Assumptions!$B$44,IF(I$4<2025,Assumptions!$B$45,Assumptions!$B$46)) -> 0.245 | J30: =IF(J$4<2022,Assumptions!$B$44,IF(J$4<2025,Assumptions!$B$45,Assumptions!$B$46)) -> 0.245 | K30: =IF(K$4<2022,Assumptions!$B$44,IF(K$4<2025,Assumptions!$B$45,Assumptions!$B$46)) -> 0.245 | ... AB30: =IF(AB$4<2022,Assumptions!$B$44,IF(AB$4<2025,Assumptions!$B$45,Assumptions!$B$46)) -> 0.245
A31: ATAD deduction cap (EUR) | C31: 0 | D31: =MAX(Assumptions!$B$43,D$30*D$21) -> 53257798 | E31: =MAX(Assumptions!$B$43,E$30*E$21) -> 35257477 | F31: =MAX(Assumptions!$B$43,F$30*F$21) -> 35004801 | G31: =MAX(Assumptions!$B$43,G$30*G$21) -> 34747072 | H31: =MAX(Assumptions!$B$43,H$30*H$21) -> 42243130 | I31: =MAX(Assumptions!$B$43,I$30*I$21) -> 41914657 | J31: =MAX(Assumptions!$B$43,J$30*J$21) -> 41579614 | K31: =MAX(Assumptions!$B$43,K$30*K$21) -> 41237870 | ... AB31: =MAX(Assumptions!$B$43,AB$30*AB$21) -> 1000000
A32: Deductible interest (EUR) | C32: 0 | D32: =MIN(D$25,D$31) -> 25562837 | E32: =MIN(E$25,E$31) -> 24068718 | F32: =MIN(F$25,F$31) -> 22546848 | G32: =MIN(G$25,G$31) -> 20996731 | H32: =MIN(H$25,H$31) -> 19417865 | I32: =MIN(I$25,I$31) -> 17809735 | J32: =MIN(J$25,J$31) -> 16171821 | K32: =MIN(K$25,K$31) -> 14503594 | ... AB32: =MIN(AB$25,AB$31) -> 0
A33: Taxable EBIT (EUR) | C33: 0 | D33: =D$21-D$22-D$32 -> 92323156 | E33: =E$21-E$22-E$32 -> 92578669 | F33: =F$21-F$22-F$32 -> 92837159 | G33: =G$21-G$22-G$32 -> 93098629 | H33: =H$21-H$22-H$32 -> 93363076 | I33: =I$21-I$22-I$32 -> 93630497 | J33: =J$21-J$22-J$32 -> 93900889 | K33: =K$21-K$22-K$32 -> 94174243 | ... AB33: =AB$21-AB$22-AB$32 -> -60438295
A34: Tax, actual (EUR) | C34: 0 | D34: =-IF(D$33<=0,0,IF(D$33<=Assumptions!$B$40,D$33*Assumptions!$B$41,Assumptions!$B$40*Assumptions!$B$41+(D$33-Assumptions!$B$40)*Assumptions!$B$42)) -> -23805774 | E34: =-IF(E$33<=0,0,IF(E$33<=Assumptions!$B$40,E$33*Assumptions!$B$41,Assumptions!$B$40*Assumptions!$B$41+(E$33-Assumptions!$B$40)*Assumptions!$B$42)) -> -23871696 | F34: =-IF(F$33<=0,0,IF(F$33<=Assumptions!$B$40,F$33*Assumptions!$B$41,Assumptions!$B$40*Assumptions!$B$41+(F$33-Assumptions!$B$40)*Assumptions!$B$42)) -> -23938387 | G34: =-IF(G$33<=0,0,IF(G$33<=Assumptions!$B$40,G$33*Assumptions!$B$41,Assumptions!$B$40*Assumptions!$B$41+(G$33-Assumptions!$B$40)*Assumptions!$B$42)) -> -24005846 | H34: =-IF(H$33<=0,0,IF(H$33<=Assumptions!$B$40,H$33*Assumptions!$B$41,Assumptions!$B$40*Assumptions!$B$41+(H$33-Assumptions!$B$40)*Assumptions!$B$42)) -> -24074074 | I34: =-IF(I$33<=0,0,IF(I$33<=Assumptions!$B$40,I$33*Assumptions!$B$41,Assumptions!$B$40*Assumptions!$B$41+(I$33-Assumptions!$B$40)*Assumptions!$B$42)) -> -24143068 | J34: =-IF(J$33<=0,0,IF(J$33<=Assumptions!$B$40,J$33*Assumptions!$B$41,Assumptions!$B$40*Assumptions!$B$41+(J$33-Assumptions!$B$40)*Assumptions!$B$42)) -> -24212829 | K34: =-IF(K$33<=0,0,IF(K$33<=Assumptions!$B$40,K$33*Assumptions!$B$41,Assumptions!$B$40*Assumptions!$B$41+(K$33-Assumptions!$B$40)*Assumptions!$B$42)) -> -24283355 | ... AB34: =-IF(AB$33<=0,0,IF(AB$33<=Assumptions!$B$40,AB$33*Assumptions!$B$41,Assumptions!$B$40*Assumptions!$B$41+(AB$33-Assumptions!$B$40)*Assumptions!$B$42)) -> 0
A35: CASH FLOW & DISTRIBUTION WATERFALL
A36: CAPEX (EUR) | C36: =-Assumptions!$B$13 -> -1491000000 | D36: 0 | E36: 0 | F36: 0 | G36: 0 | H36: 0 | I36: 0 | J36: 0 | K36: 0 | L36: 0 | M36: 0 | N36: 0 | O36: 0 | P36: 0 | Q36: 0 | R36: 0 | S36: 0 | T36: 0 | U36: 0 | V36: 0 | W36: 0 | X36: 0 | Y36: 0 | Z36: 0 | AA36: 0 | AB36: 0
A37: Debt drawn (EUR) | C37: ='Debt Sizing'!$B$23 -> 9.1985741e+08 | D37: 0 | E37: 0 | F37: 0 | G37: 0 | H37: 0 | I37: 0 | J37: 0 | K37: 0 | L37: 0 | M37: 0 | N37: 0 | O37: 0 | P37: 0 | Q37: 0 | R37: 0 | S37: 0 | T37: 0 | U37: 0 | V37: 0 | W37: 0 | X37: 0 | Y37: 0 | Z37: 0 | AA37: 0 | AB37: 0
A38: Equity drawn, incl. DSRA pre-funding (EUR) | C38: =-(C36+C37)+C41 -> 6.1080633e+08 | D38: 0 | E38: 0 | F38: 0 | G38: 0 | H38: 0 | I38: 0 | J38: 0 | K38: 0 | L38: 0 | M38: 0 | N38: 0 | O38: 0 | P38: 0 | Q38: 0 | R38: 0 | S38: 0 | T38: 0 | U38: 0 | V38: 0 | W38: 0 | X38: 0 | Y38: 0 | Z38: 0 | AA38: 0 | AB38: 0
A39: CFADS, actual (EBITDA + tax, before debt service) | C39: 0 | D39: =D$21+D$34 -> 1.5372022e+08 | E39: =E$21+E$34 -> 1.5241569e+08 | F39: =F$21+F$34 -> 1.5108562e+08 | G39: =G$21+G$34 -> 1.4972951e+08 | H39: =H$21+H$34 -> 1.4834687e+08 | I39: =I$21+I$34 -> 1.4693716e+08 | J39: =J$21+J$34 -> 1.4549988e+08 | K39: =K$21+K$34 -> 1.4403448e+08 | ... AB39: =AB$21+AB$34 -> -798295.32
A40: Residual cash flow (after debt service) | C40: 0 | D40: =D$39-D$26 -> 74392741 | E40: =E$39-E$26 -> 73583747 | F40: =F$39-F$26 -> 72759123 | G40: =G$39-G$26 -> 71918572 | H40: =H$39-H$26 -> 71061791 | I40: =I$39-I$26 -> 70188471 | J40: =J$39-J$26 -> 69298299 | K40: =K$39-K$26 -> 68390954 | ... AB40: =AB$39-AB$26 -> -798295.32
A41: DSRA target (EUR) | C41: ='Debt Sizing'!$B$29*Assumptions!$B$38/12 -> 39663739 | D41: =E$26*Assumptions!$B$38/12 -> 39415972 | E41: =F$26*Assumptions!$B$38/12 -> 39163249 | F41: =G$26*Assumptions!$B$38/12 -> 38905471 | G41: =H$26*Assumptions!$B$38/12 -> 38642538 | H41: =I$26*Assumptions!$B$38/12 -> 38374346 | I41: =J$26*Assumptions!$B$38/12 -> 38100791 | J41: =K$26*Assumptions!$B$38/12 -> 37821764 | K41: =L$26*Assumptions!$B$38/12 -> 37537157 | ... AA41: =AB$26*Assumptions!$B$38/12 -> 0 | AB41: 0
A42: DSRA opening balance (EUR) | C42: 0 | D42: =D$41 -> 39415972 | E42: =D$41 -> 39415972 | F42: =E$41 -> 39163249 | G42: =F$41 -> 38905471 | H42: =G$41 -> 38642538 | I42: =H$41 -> 38374346 | J42: =I$41 -> 38100791 | K42: =J$41 -> 37821764 | L42: =K$41 -> 37537157 | ... AB42: =AA$41 -> 0
A43: DSRA movement (funding) / release (EUR) | C43: 0 | D43: =D$41-D$42 -> 0 | E43: =E$41-E$42 -> -252723.03 | F43: =F$41-F$42 -> -257777.49 | G43: =G$41-G$42 -> -262933.04 | H43: =H$41-H$42 -> -268191.7 | I43: =I$41-I$42 -> -273555.54 | J43: =J$41-J$42 -> -279026.65 | K43: =K$41-K$42 -> -284607.18 | ... AB43: =AB$41-AB$42 -> 0
A44: DSCR, historic (current year) | C44: n/a | D44: =IF(D$26=0,"n/a",D$39/D$26) -> 1.9377928 | E44: =IF(E$26=0,"n/a",E$39/E$26) -> 1.9334255 | F44: =IF(F$26=0,"n/a",F$39/F$26) -> 1.9289209 | G44: =IF(G$26=0,"n/a",G$39/G$26) -> 1.9242732 | H44: =IF(H$26=0,"n/a",H$39/H$26) -> 1.9194762 | I44: =IF(I$26=0,"n/a",I$39/I$26) -> 1.9145233 | J44: =IF(J$26=0,"n/a",J$39/J$26) -> 1.9094076 | K44: =IF(K$26=0,"n/a",K$39/K$26) -> 1.9041217 | ... AB44: =IF(AB$26=0,"n/a",AB$39/AB$26) -> n/a
...

Sheet Stress Tests
A1: Stress Tests
A4: Operational year | B4: 1 | C4: 2 | D4: 3 | E4: 4 | F4: 5 | G4: 6 | H4: 7 | I4: 8 | J4: 9 | K4: 10 | L4: 11 | M4: 12 | N4: 13 | O4: 14 | P4: 15
A5: Debt service (base case, EUR) | B5: ='Cash Flow & Waterfall'!$D$26 -> 79327478 | C5: ='Cash Flow & Waterfall'!$E$26 -> 78831943 | D5: ='Cash Flow & Waterfall'!$F$26 -> 78326497 | E5: ='Cash Flow & Waterfall'!$G$26 -> 77810942 | F5: ='Cash Flow & Waterfall'!$H$26 -> 77285076 | G5: ='Cash Flow & Waterfall'!$I$26 -> 76748693 | H5: ='Cash Flow & Waterfall'!$J$26 -> 76201581 | I5: ='Cash Flow & Waterfall'!$K$26 -> 75643528 | J5: ='Cash Flow & Waterfall'!$L$26 -> 75074314 | K5: ='Cash Flow & Waterfall'!$M$26 -> 74493715 | L5: ='Cash Flow & Waterfall'!$N$26 -> 73901505 | M5: ='Cash Flow & Waterfall'!$O$26 -> 73297450 | N5: ='Cash Flow & Waterfall'!$P$26 -> 72681314 | O5: ='Cash Flow & Waterfall'!$Q$26 -> 72052855 | P5: ='Cash Flow & Waterfall'!$R$26 -> 71411827
A7: SCENARIO: Base case (P50, ex-ante price)
A8: Production (MWh) | B8: =Assumptions!$B$6*Assumptions!$B$7*8760*(1-Assumptions!$B$8)^(B$4-1) -> 3293760 | C8: =Assumptions!$B$6*Assumptions!$B$7*8760*(1-Assumptions!$B$8)^(C$4-1) -> 3293760 | D8: =Assumptions!$B$6*Assumptions!$B$7*8760*(1-Assumptions!$B$8)^(D$4-1) -> 3293760 | E8: =Assumptions!$B$6*Assumptions!$B$7*8760*(1-Assumptions!$B$8)^(E$4-1) -> 3293760 | F8: =Assumptions!$B$6*Assumptions!$B$7*8760*(1-Assumptions!$B$8)^(F$4-1) -> 3293760 | G8: =Assumptions!$B$6*Assumptions!$B$7*8760*(1-Assumptions!$B$8)^(G$4-1) -> 3293760 | H8: =Assumptions!$B$6*Assumptions!$B$7*8760*(1-Assumptions!$B$8)^(H$4-1) -> 3293760 | I8: =Assumptions!$B$6*Assumptions!$B$7*8760*(1-Assumptions!$B$8)^(I$4-1) -> 3293760 | ... P8: =Assumptions!$B$6*Assumptions!$B$7*8760*(1-Assumptions!$B$8)^(P$4-1) -> 3293760
A9: Market price (EUR/MWh) | B9: =Assumptions!$B$24 -> 30 | C9: =Assumptions!$B$24 -> 30 | D9: =Assumptions!$B$24 -> 30 | E9: =Assumptions!$B$24 -> 30 | F9: =Assumptions!$B$24 -> 30 | G9: =Assumptions!$B$24 -> 30 | H9: =Assumptions!$B$24 -> 30 | I9: =Assumptions!$B$24 -> 30 | ... P9: =Assumptions!$B$24 -> 30
A10: Total price incl. subsidy (EUR/MWh) | B10: =B$9+MAX(0,Assumptions!$B$21-MAX(B$9,Assumptions!$B$22)) -> 72.7 | C10: =C$9+MAX(0,Assumptions!$B$21-MAX(C$9,Assumptions!$B$22)) -> 72.7 | D10: =D$9+MAX(0,Assumptions!$B$21-MAX(D$9,Assumptions!$B$22)) -> 72.7 | E10: =E$9+MAX(0,Assumptions!$B$21-MAX(E$9,Assumptions!$B$22)) -> 72.7 | F10: =F$9+MAX(0,Assumptions!$B$21-MAX(F$9,Assumptions!$B$22)) -> 72.7 | G10: =G$9+MAX(0,Assumptions!$B$21-MAX(G$9,Assumptions!$B$22)) -> 72.7 | H10: =H$9+MAX(0,Assumptions!$B$21-MAX(H$9,Assumptions!$B$22)) -> 72.7 | I10: =I$9+MAX(0,Assumptions!$B$21-MAX(I$9,Assumptions!$B$22)) -> 72.7 | ... P10: =P$9+MAX(0,Assumptions!$B$21-MAX(P$9,Assumptions!$B$22)) -> 72.7
A11: Revenue (EUR) | B11: =B$8*B$10 -> 239456352 | C11: =C$8*C$10 -> 239456352 | D11: =D$8*D$10 -> 239456352 | E11: =E$8*E$10 -> 239456352 | F11: =F$8*F$10 -> 239456352 | G11: =G$8*G$10 -> 239456352 | H11: =H$8*H$10 -> 239456352 | I11: =I$8*I$10 -> 239456352 | ... P11: =P$8*P$10 -> 239456352
A12: OPEX (EUR) | B12: =(Assumptions!$B$17*(1+Assumptions!$B$19)^(B$4-1)*B$8)+(Assumptions!$B$18*(1+Assumptions!$B$19)^(B$4-1)*Assumptions!$B$6) -> 61930358 | C12: =(Assumptions!$B$17*(1+Assumptions!$B$19)^(C$4-1)*C$8)+(Assumptions!$B$18*(1+Assumptions!$B$19)^(C$4-1)*Assumptions!$B$6) -> 63168966 | D12: =(Assumptions!$B$17*(1+Assumptions!$B$19)^(D$4-1)*D$8)+(Assumptions!$B$18*(1+Assumptions!$B$19)^(D$4-1)*Assumptions!$B$6) -> 64432345 | E12: =(Assumptions!$B$17*(1+Assumptions!$B$19)^(E$4-1)*E$8)+(Assumptions!$B$18*(1+Assumptions!$B$19)^(E$4-1)*Assumptions!$B$6) -> 65720992 | F12: =(Assumptions!$B$17*(1+Assumptions!$B$19)^(F$4-1)*F$8)+(Assumptions!$B$18*(1+Assumptions!$B$19)^(F$4-1)*Assumptions!$B$6) -> 67035412 | G12: =(Assumptions!$B$17*(1+Assumptions!$B$19)^(G$4-1)*G$8)+(Assumptions!$B$18*(1+Assumptions!$B$19)^(G$4-1)*Assumptions!$B$6) -> 68376120 | H12: =(Assumptions!$B$17*(1+Assumptions!$B$19)^(H$4-1)*H$8)+(Assumptions!$B$18*(1+Assumptions!$B$19)^(H$4-1)*Assumptions!$B$6) -> 69743642 | I12: =(Assumptions!$B$17*(1+Assumptions!$B$19)^(I$4-1)*I$8)+(Assumptions!$B$18*(1+Assumptions!$B$19)^(I$4-1)*Assumptions!$B$6) -> 71138515 | ... P12: =(Assumptions!$B$17*(1+Assumptions!$B$19)^(P$4-1)*P$8)+(Assumptions!$B$18*(1+Assumptions!$B$19)^(P$4-1)*Assumptions!$B$6) -> 81715793
A13: EBITDA (EUR) | B13: =B$11-B$12 -> 1.7752599e+08 | C13: =C$11-C$12 -> 1.7628739e+08 | D13: =D$11-D$12 -> 1.7502401e+08 | E13: =E$11-E$12 -> 1.7373536e+08 | F13: =F$11-F$12 -> 1.7242094e+08 | G13: =G$11-G$12 -> 1.7108023e+08 | H13: =H$11-H$12 -> 1.6971271e+08 | I13: =I$11-I$12 -> 1.6831784e+08 | ... P13: =P$11-P$12 -> 1.5774056e+08
A14: Tax, approx. (EUR) | B14: =-MAX(0,(B$13-Assumptions!$B$13/Assumptions!$B$59)*Assumptions!$B$42) -> -30414586 | C14: =-MAX(0,(C$13-Assumptions!$B$13/Assumptions!$B$59)*Assumptions!$B$42) -> -30095026 | D14: =-MAX(0,(D$13-Assumptions!$B$13/Assumptions!$B$59)*Assumptions!$B$42) -> -29769074 | E14: =-MAX(0,(E$13-Assumptions!$B$13/Assumptions!$B$59)*Assumptions!$B$42) -> -29436603 | F14: =-MAX(0,(F$13-Assumptions!$B$13/Assumptions!$B$59)*Assumptions!$B$42) -> -29097483 | G14: =-MAX(0,(G$13-Assumptions!$B$13/Assumptions!$B$59)*Assumptions!$B$42) -> -28751580 | H14: =-MAX(0,(H$13-Assumptions!$B$13/Assumptions!$B$59)*Assumptions!$B$42) -> -28398759 | I14: =-MAX(0,(I$13-Assumptions!$B$13/Assumptions!$B$59)*Assumptions!$B$42) -> -28038882 | ... P14: =-MAX(0,(P$13-Assumptions!$B$13/Assumptions!$B$59)*Assumptions!$B$42) -> -25309944
A15: CFADS (EUR) | B15: =B$13+B$14 -> 1.4711141e+08 | C15: =C$13+C$14 -> 1.4619236e+08 | D15: =D$13+D$14 -> 1.4525493e+08 | E15: =E$13+E$14 -> 1.4429876e+08 | F15: =F$13+F$14 -> 1.4332346e+08 | G15: =G$13+G$14 -> 1.4232865e+08 | H15: =H$13+H$14 -> 1.4131395e+08 | I15: =I$13+I$14 -> 1.4027895e+08 | ... P15: =P$13+P$14 -> 1.3243062e+08
A16: DSCR | B16: =B$15/B$5 -> 1.8544823 | C16: =C$15/C$5 -> 1.8544813 | D16: =D$15/D$5 -> 1.8544801 | E16: =E$15/E$5 -> 1.854479 | F16: =F$15/F$5 -> 1.8544778 | G16: =G$15/G$5 -> 1.8544766 | H16: =H$15/H$5 -> 1.8544753 | I16: =I$15/I$5 -> 1.854474 | ... P16: =P$15/P$5 -> 1.8544633
A17: Min DSCR / Historic breaches / Forward breaches / Lock-up fails | B17: =MIN(B16:P16) -> 1.8544633 | D17: =COUNTIF(B16:P16,"<"&Assumptions!$B$33) -> 0 | F17: =COUNTIF(B16:P16,"<"&Assumptions!$B$34) -> 0 | H17: =COUNTIF(B16:P16,"<"&Assumptions!$B$35) -> 0
A19: SCENARIO: P90 production
A20: Production (MWh) | B20: =Assumptions!$B$6*Assumptions!$B$10*8760*(1-Assumptions!$B$8)^(B$4-1) -> 2871647.7 | C20: =Assumptions!$B$6*Assumptions!$B$10*8760*(1-Assumptions!$B$8)^(C$4-1) -> 2871647.7 | D20: =Assumptions!$B$6*Assumptions!$B$10*8760*(1-Assumptions!$B$8)^(D$4-1) -> 2871647.7 | E20: =Assumptions!$B$6*Assumptions!$B$10*8760*(1-Assumptions!$B$8)^(E$4-1) -> 2871647.7 | F20: =Assumptions!$B$6*Assumptions!$B$10*8760*(1-Assumptions!$B$8)^(F$4-1) -> 2871647.7 | G20: =Assumptions!$B$6*Assumptions!$B$10*8760*(1-Assumptions!$B$8)^(G$4-1) -> 2871647.7 | H20: =Assumptions!$B$6*Assumptions!$B$10*8760*(1-Assumptions!$B$8)^(H$4-1) -> 2871647.7 | I20: =Assumptions!$B$6*Assumptions!$B$10*8760*(1-Assumptions!$B$8)^(I$4-1) -> 2871647.7 | ... P20: =Assumptions!$B$6*Assumptions!$B$10*8760*(1-Assumptions!$B$8)^(P$4-1) -> 2871647.7
A21: Market price (EUR/MWh) | B21: =Assumptions!$B$24 -> 30 | C21: =Assumptions!$B$24 -> 30 | D21: =Assumptions!$B$24 -> 30 | E21: =Assumptions!$B$24 -> 30 | F21: =Assumptions!$B$24 -> 30 | G21: =Assumptions!$B$24 -> 30 | H21: =Assumptions!$B$24 -> 30 | I21: =Assumptions!$B$24 -> 30 | ... P21: =Assumptions!$B$24 -> 30
A22: Total price incl. subsidy (EUR/MWh) | B22: =B$21+MAX(0,Assumptions!$B$21-MAX(B$21,Assumptions!$B$22)) -> 72.7 | C22: =C$21+MAX(0,Assumptions!$B$21-MAX(C$21,Assumptions!$B$22)) -> 72.7 | D22: =D$21+MAX(0,Assumptions!$B$21-MAX(D$21,Assumptions!$B$22)) -> 72.7 | E22: =E$21+MAX(0,Assumptions!$B$21-MAX(E$21,Assumptions!$B$22)) -> 72.7 | F22: =F$21+MAX(0,Assumptions!$B$21-MAX(F$21,Assumptions!$B$22)) -> 72.7 | G22: =G$21+MAX(0,Assumptions!$B$21-MAX(G$21,Assumptions!$B$22)) -> 72.7 | H22: =H$21+MAX(0,Assumptions!$B$21-MAX(H$21,Assumptions!$B$22)) -> 72.7 | I22: =I$21+MAX(0,Assumptions!$B$21-MAX(I$21,Assumptions!$B$22)) -> 72.7 | ... P22: =P$21+MAX(0,Assumptions!$B$21-MAX(P$21,Assumptions!$B$22)) -> 72.7
A23: Revenue (EUR) | B23: =B$20*B$22 -> 2.0876879e+08 | C23: =C$20*C$22 -> 2.0876879e+08 | D23: =D$20*D$22 -> 2.0876879e+08 | E23: =E$20*E$22 -> 2.0876879e+08 | F23: =F$20*F$22 -> 2.0876879e+08 | G23: =G$20*G$22 -> 2.0876879e+08 | H23: =H$20*H$22 -> 2.0876879e+08 | I23: =I$20*I$22 -> 2.0876879e+08 | ... P23: =P$20*P$22 -> 2.0876879e+08
A24: OPEX (EUR) | B24: =(Assumptions!$B$17*(1+Assumptions!$B$19)^(B$4-1)*B$20)+(Assumptions!$B$18*(1+Assumptions!$B$19)^(B$4-1)*Assumptions!$B$6) -> 57882301 | C24: =(Assumptions!$B$17*(1+Assumptions!$B$19)^(C$4-1)*C$20)+(Assumptions!$B$18*(1+Assumptions!$B$19)^(C$4-1)*Assumptions!$B$6) -> 59039947 | D24: =(Assumptions!$B$17*(1+Assumptions!$B$19)^(D$4-1)*D$20)+(Assumptions!$B$18*(1+Assumptions!$B$19)^(D$4-1)*Assumptions!$B$6) -> 60220746 | E24: =(Assumptions!$B$17*(1+Assumptions!$B$19)^(E$4-1)*E$20)+(Assumptions!$B$18*(1+Assumptions!$B$19)^(E$4-1)*Assumptions!$B$6) -> 61425161 | F24: =(Assumptions!$B$17*(1+Assumptions!$B$19)^(F$4-1)*F$20)+(Assumptions!$B$18*(1+Assumptions!$B$19)^(F$4-1)*Assumptions!$B$6) -> 62653664 | G24: =(Assumptions!$B$17*(1+Assumptions!$B$19)^(G$4-1)*G$20)+(Assumptions!$B$18*(1+Assumptions!$B$19)^(G$4-1)*Assumptions!$B$6) -> 63906738 | H24: =(Assumptions!$B$17*(1+Assumptions!$B$19)^(H$4-1)*H$20)+(Assumptions!$B$18*(1+Assumptions!$B$19)^(H$4-1)*Assumptions!$B$6) -> 65184872 | I24: =(Assumptions!$B$17*(1+Assumptions!$B$19)^(I$4-1)*I$20)+(Assumptions!$B$18*(1+Assumptions!$B$19)^(I$4-1)*Assumptions!$B$6) -> 66488570 | ... P24: =(Assumptions!$B$17*(1+Assumptions!$B$19)^(P$4-1)*P$20)+(Assumptions!$B$18*(1+Assumptions!$B$19)^(P$4-1)*Assumptions!$B$6) -> 76374467
A25: EBITDA (EUR) | B25: =B$23-B$24 -> 1.5088648e+08 | C25: =C$23-C$24 -> 1.4972884e+08 | D25: =D$23-D$24 -> 1.4854804e+08 | E25: =E$23-E$24 -> 1.4734362e+08 | F25: =F$23-F$24 -> 1.4611512e+08 | G25: =G$23-G$24 -> 1.4486205e+08 | H25: =H$23-H$24 -> 1.4358391e+08 | I25: =I$23-I$24 -> 1.4228022e+08 | ... P25: =P$23-P$24 -> 1.3239432e+08
A26: Tax, approx. (EUR) | B26: =-MAX(0,(B$25-Assumptions!$B$13/Assumptions!$B$59)*Assumptions!$B$42) -> -23541593 | C26: =-MAX(0,(C$25-Assumptions!$B$13/Assumptions!$B$59)*Assumptions!$B$42) -> -23242920 | D26: =-MAX(0,(D$25-Assumptions!$B$13/Assumptions!$B$59)*Assumptions!$B$42) -> -22938274 | E26: =-MAX(0,(E$25-Assumptions!$B$13/Assumptions!$B$59)*Assumptions!$B$42) -> -22627535 | F26: =-MAX(0,(F$25-Assumptions!$B$13/Assumptions!$B$59)*Assumptions!$B$42) -> -22310581 | G26: =-MAX(0,(G$25-Assumptions!$B$13/Assumptions!$B$59)*Assumptions!$B$42) -> -21987288 | H26: =-MAX(0,(H$25-Assumptions!$B$13/Assumptions!$B$59)*Assumptions!$B$42) -> -21657530 | I26: =-MAX(0,(I$25-Assumptions!$B$13/Assumptions!$B$59)*Assumptions!$B$42) -> -21321176 | ... P26: =-MAX(0,(P$25-Assumptions!$B$13/Assumptions!$B$59)*Assumptions!$B$42) -> -18770614
A27: CFADS (EUR) | B27: =B$25+B$26 -> 1.2734489e+08 | C27: =C$25+C$26 -> 1.2648592e+08 | D27: =D$25+D$26 -> 1.2560977e+08 | E27: =E$25+E$26 -> 1.2471609e+08 | F27: =F$25+F$26 -> 1.2380454e+08 | G27: =G$25+G$26 -> 1.2287476e+08 | H27: =H$25+H$26 -> 1.2192638e+08 | I27: =I$25+I$26 -> 1.2095904e+08 | ... P27: =P$25+P$26 -> 1.136237e+08
A28: DSCR | B28: =B$27/B$5 -> 1.6053062 | C28: =C$27/C$5 -> 1.6045008 | D28: =D$27/D$5 -> 1.6036689 | E28: =E$27/E$5 -> 1.6028091 | F28: =F$27/F$5 -> 1.6019204 | G28: =G$27/G$5 -> 1.6010013 | H28: =H$27/H$5 -> 1.6000506 | I28: =I$27/I$5 -> 1.5990666 | ... P28: =P$27/P$5 -> 1.5911048
A29: Min DSCR / Historic breaches / Forward breaches / Lock-up fails | B29: =MIN(B28:P28) -> 1.5911048 | D29: =COUNTIF(B28:P28,"<"&Assumptions!$B$33) -> 0 | F29: =COUNTIF(B28:P28,"<"&Assumptions!$B$34) -> 0 | H29: =COUNTIF(B28:P28,"<"&Assumptions!$B$35) -> 0
A31: SCENARIO: Price shock (ex-ante -20%)
A32: Production (MWh) | B32: =Assumptions!$B$6*Assumptions!$B$7*8760*(1-Assumptions!$B$8)^(B$4-1) -> 3293760 | C32: =Assumptions!$B$6*Assumptions!$B$7*8760*(1-Assumptions!$B$8)^(C$4-1) -> 3293760 | D32: =Assumptions!$B$6*Assumptions!$B$7*8760*(1-Assumptions!$B$8)^(D$4-1) -> 3293760 | E32: =Assumptions!$B$6*Assumptions!$B$7*8760*(1-Assumptions!$B$8)^(E$4-1) -> 3293760 | F32: =Assumptions!$B$6*Assumptions!$B$7*8760*(1-Assumptions!$B$8)^(F$4-1) -> 3293760 | G32: =Assumptions!$B$6*Assumptions!$B$7*8760*(1-Assumptions!$B$8)^(G$4-1) -> 3293760 | H32: =Assumptions!$B$6*Assumptions!$B$7*8760*(1-Assumptions!$B$8)^(H$4-1) -> 3293760 | I32: =Assumptions!$B$6*Assumptions!$B$7*8760*(1-Assumptions!$B$8)^(I$4-1) -> 3293760 | ... P32: =Assumptions!$B$6*Assumptions!$B$7*8760*(1-Assumptions!$B$8)^(P$4-1) -> 3293760
A33: Market price (EUR/MWh) | B33: =Assumptions!$B$24*(1+Assumptions!$B$25) -> 24 | C33: =Assumptions!$B$24*(1+Assumptions!$B$25) -> 24 | D33: =Assumptions!$B$24*(1+Assumptions!$B$25) -> 24 | E33: =Assumptions!$B$24*(1+Assumptions!$B$25) -> 24 | F33: =Assumptions!$B$24*(1+Assumptions!$B$25) -> 24 | G33: =Assumptions!$B$24*(1+Assumptions!$B$25) -> 24 | H33: =Assumptions!$B$24*(1+Assumptions!$B$25) -> 24 | I33: =Assumptions!$B$24*(1+Assumptions!$B$25) -> 24 | ... P33: =Assumptions!$B$24*(1+Assumptions!$B$25) -> 24
A34: Total price incl. subsidy (EUR/MWh) | B34: =B$33+MAX(0,Assumptions!$B$21-MAX(B$33,Assumptions!$B$22)) -> 67.7 | C34: =C$33+MAX(0,Assumptions!$B$21-MAX(C$33,Assumptions!$B$22)) -> 67.7 | D34: =D$33+MAX(0,Assumptions!$B$21-MAX(D$33,Assumptions!$B$22)) -> 67.7 | E34: =E$33+MAX(0,Assumptions!$B$21-MAX(E$33,Assumptions!$B$22)) -> 67.7 | F34: =F$33+MAX(0,Assumptions!$B$21-MAX(F$33,Assumptions!$B$22)) -> 67.7 | G34: =G$33+MAX(0,Assumptions!$B$21-MAX(G$33,Assumptions!$B$22)) -> 67.7 | H34: =H$33+MAX(0,Assumptions!$B$21-MAX(H$33,Assumptions!$B$22)) -> 67.7 | I34: =I$33+MAX(0,Assumptions!$B$21-MAX(I$33,Assumptions!$B$22)) -> 67.7 | ... P34: =P$33+MAX(0,Assumptions!$B$21-MAX(P$33,Assumptions!$B$22)) -> 67.7
A35: Revenue (EUR) | B35: =B$32*B$34 -> 222987552 | C35: =C$32*C$34 -> 222987552 | D35: =D$32*D$34 -> 222987552 | E35: =E$32*E$34 -> 222987552 | F35: =F$32*F$34 -> 222987552 | G35: =G$32*G$34 -> 222987552 | H35: =H$32*H$34 -> 222987552 | I35: =I$32*I$34 -> 222987552 | ... P35: =P$32*P$34 -> 222987552
A36: OPEX (EUR) | B36: =(Assumptions!$B$17*(1+Assumptions!$B$19)^(B$4-1)*B$32)+(Assumptions!$B$18*(1+Assumptions!$B$19)^(B$4-1)*Assumptions!$B$6) -> 61930358 | C36: =(Assumptions!$B$17*(1+Assumptions!$B$19)^(C$4-1)*C$32)+(Assumptions!$B$18*(1+Assumptions!$B$19)^(C$4-1)*Assumptions!$B$6) -> 63168966 | D36: =(Assumptions!$B$17*(1+Assumptions!$B$19)^(D$4-1)*D$32)+(Assumptions!$B$18*(1+Assumptions!$B$19)^(D$4-1)*Assumptions!$B$6) -> 64432345 | E36: =(Assumptions!$B$17*(1+Assumptions!$B$19)^(E$4-1)*E$32)+(Assumptions!$B$18*(1+Assumptions!$B$19)^(E$4-1)*Assumptions!$B$6) -> 65720992 | F36: =(Assumptions!$B$17*(1+Assumptions!$B$19)^(F$4-1)*F$32)+(Assumptions!$B$18*(1+Assumptions!$B$19)^(F$4-1)*Assumptions!$B$6) -> 67035412 | G36: =(Assumptions!$B$17*(1+Assumptions!$B$19)^(G$4-1)*G$32)+(Assumptions!$B$18*(1+Assumptions!$B$19)^(G$4-1)*Assumptions!$B$6) -> 68376120 | H36: =(Assumptions!$B$17*(1+Assumptions!$B$19)^(H$4-1)*H$32)+(Assumptions!$B$18*(1+Assumptions!$B$19)^(H$4-1)*Assumptions!$B$6) -> 69743642 | I36: =(Assumptions!$B$17*(1+Assumptions!$B$19)^(I$4-1)*I$32)+(Assumptions!$B$18*(1+Assumptions!$B$19)^(I$4-1)*Assumptions!$B$6) -> 71138515 | ... P36: =(Assumptions!$B$17*(1+Assumptions!$B$19)^(P$4-1)*P$32)+(Assumptions!$B$18*(1+Assumptions!$B$19)^(P$4-1)*Assumptions!$B$6) -> 81715793
A37: EBITDA (EUR) | B37: =B$35-B$36 -> 1.6105719e+08 | C37: =C$35-C$36 -> 1.5981859e+08 | D37: =D$35-D$36 -> 1.5855521e+08 | E37: =E$35-E$36 -> 1.5726656e+08 | F37: =F$35-F$36 -> 1.5595214e+08 | G37: =G$35-G$36 -> 1.5461143e+08 | H37: =H$35-H$36 -> 1.5324391e+08 | I37: =I$35-I$36 -> 1.5184904e+08 | ... P37: =P$35-P$36 -> 1.4127176e+08
A38: Tax, approx. (EUR) | B38: =-MAX(0,(B$37-Assumptions!$B$13/Assumptions!$B$59)*Assumptions!$B$42) -> -26165636 | C38: =-MAX(0,(C$37-Assumptions!$B$13/Assumptions!$B$59)*Assumptions!$B$42) -> -25846075 | D38: =-MAX(0,(D$37-Assumptions!$B$13/Assumptions!$B$59)*Assumptions!$B$42) -> -25520123 | E38: =-MAX(0,(E$37-Assumptions!$B$13/Assumptions!$B$59)*Assumptions!$B$42) -> -25187653 | F38: =-MAX(0,(F$37-Assumptions!$B$13/Assumptions!$B$59)*Assumptions!$B$42) -> -24848532 | G38: =-MAX(0,(G$37-Assumptions!$B$13/Assumptions!$B$59)*Assumptions!$B$42) -> -24502629 | H38: =-MAX(0,(H$37-Assumptions!$B$13/Assumptions!$B$59)*Assumptions!$B$42) -> -24149809 | I38: =-MAX(0,(I$37-Assumptions!$B$13/Assumptions!$B$59)*Assumptions!$B$42) -> -23789932 | ... P38: =-MAX(0,(P$37-Assumptions!$B$13/Assumptions!$B$59)*Assumptions!$B$42) -> -21060994
A39: CFADS (EUR) | B39: =B$37+B$38 -> 1.3489156e+08 | C39: =C$37+C$38 -> 1.3397251e+08 | D39: =D$37+D$38 -> 1.3303508e+08 | E39: =E$37+E$38 -> 1.3207891e+08 | F39: =F$37+F$38 -> 1.3110361e+08 | G39: =G$37+G$38 -> 1.301088e+08 | H39: =H$37+H$38 -> 1.290941e+08 | I39: =I$37+I$38 -> 1.2805911e+08 | ... P39: =P$37+P$38 -> 1.2021077e+08
A40: DSCR | B40: =B$39/B$5 -> 1.7004392 | C40: =C$39/C$5 -> 1.6994699 | D40: =D$39/D$5 -> 1.6984684 | E40: =E$39/E$5 -> 1.6974336 | F40: =F$39/F$5 -> 1.6963638 | G40: =G$39/G$5 -> 1.6952576 | H40: =H$39/H$5 -> 1.6941131 | I40: =I$39/I$5 -> 1.6929288 | ... P40: =P$39/P$5 -> 1.6833453
A41: Min DSCR / Historic breaches / Forward breaches / Lock-up fails | B41: =MIN(B40:P40) -> 1.6833453 | D41: =COUNTIF(B40:P40,"<"&Assumptions!$B$33) -> 0 | F41: =COUNTIF(B40:P40,"<"&Assumptions!$B$34) -> 0 | H41: =COUNTIF(B40:P40,"<"&Assumptions!$B$35) -> 0
A43: SCENARIO: Combined stress (P90 + price shock)
A44: Production (MWh) | B44: =Assumptions!$B$6*Assumptions!$B$10*8760*(1-Assumptions!$B$8)^(B$4-1) -> 2871647.7 | C44: =Assumptions!$B$6*Assumptions!$B$10*8760*(1-Assumptions!$B$8)^(C$4-1) -> 2871647.7 | D44: =Assumptions!$B$6*Assumptions!$B$10*8760*(1-Assumptions!$B$8)^(D$4-1) -> 2871647.7 | E44: =Assumptions!$B$6*Assumptions!$B$10*8760*(1-Assumptions!$B$8)^(E$4-1) -> 2871647.7 | F44: =Assumptions!$B$6*Assumptions!$B$10*8760*(1-Assumptions!$B$8)^(F$4-1) -> 2871647.7 | G44: =Assumptions!$B$6*Assumptions!$B$10*8760*(1-Assumptions!$B$8)^(G$4-1) -> 2871647.7 | H44: =Assumptions!$B$6*Assumptions!$B$10*8760*(1-Assumptions!$B$8)^(H$4-1) -> 2871647.7 | I44: =Assumptions!$B$6*Assumptions!$B$10*8760*(1-Assumptions!$B$8)^(I$4-1) -> 2871647.7 | ... P44: =Assumptions!$B$6*Assumptions!$B$10*8760*(1-Assumptions!$B$8)^(P$4-1) -> 2871647.7
A45: Market price (EUR/MWh) | B45: =Assumptions!$B$24*(1+Assumptions!$B$25) -> 24 | C45: =Assumptions!$B$24*(1+Assumptions!$B$25) -> 24 | D45: =Assumptions!$B$24*(1+Assumptions!$B$25) -> 24 | E45: =Assumptions!$B$24*(1+Assumptions!$B$25) -> 24 | F45: =Assumptions!$B$24*(1+Assumptions!$B$25) -> 24 | G45: =Assumptions!$B$24*(1+Assumptions!$B$25) -> 24 | H45: =Assumptions!$B$24*(1+Assumptions!$B$25) -> 24 | I45: =Assumptions!$B$24*(1+Assumptions!$B$25) -> 24 | ... P45: =Assumptions!$B$24*(1+Assumptions!$B$25) -> 24
A46: Total price incl. subsidy (EUR/MWh) | B46: =B$45+MAX(0,Assumptions!$B$21-MAX(B$45,Assumptions!$B$22)) -> 67.7 | C46: =C$45+MAX(0,Assumptions!$B$21-MAX(C$45,Assumptions!$B$22)) -> 67.7 | D46: =D$45+MAX(0,Assumptions!$B$21-MAX(D$45,Assumptions!$B$22)) -> 67.7 | E46: =E$45+MAX(0,Assumptions!$B$21-MAX(E$45,Assumptions!$B$22)) -> 67.7 | F46: =F$45+MAX(0,Assumptions!$B$21-MAX(F$45,Assumptions!$B$22)) -> 67.7 | G46: =G$45+MAX(0,Assumptions!$B$21-MAX(G$45,Assumptions!$B$22)) -> 67.7 | H46: =H$45+MAX(0,Assumptions!$B$21-MAX(H$45,Assumptions!$B$22)) -> 67.7 | I46: =I$45+MAX(0,Assumptions!$B$21-MAX(I$45,Assumptions!$B$22)) -> 67.7 | ... P46: =P$45+MAX(0,Assumptions!$B$21-MAX(P$45,Assumptions!$B$22)) -> 67.7
...

Sheet Dashboard
A1: Key outputs
A4: Debt sizing
A5: Metric | B5: Value | D5: Note
A6: Actual initial debt balance (EUR m) | B6: ='Debt Sizing'!$B$23/1000000 -> 919.85741 | D6: Lower of DSCR / leverage cap / LLCR tests
A7: Binding constraint | B7: ='Debt Sizing'!$B$26 -> LLCR | D7: Determines which test sizes the facility
A8: Implied gearing (% of CAPEX) | B8: ='Debt Sizing'!$B$23/Assumptions!$B$13 -> 0.61693991 | D8: vs. 70% leverage cap
A9: Realised base-case DSCR (flat, yrs 1-15) | B9: ='Debt Sizing'!$B$25 -> 1.8546538 | D9: vs. 1.30x sculpting target
A10: LLCR at financial close | B10: ='Debt Sizing'!$B$31 -> 1.4 | D10: vs. 1.40x minimum (binding)
A12: Stress test summary (minimum DSCR, years 1-15)
A13: Scenario | B13: Min DSCR | C13: vs. Lock-up (1.20x) | D13: Note
A14: Base case (P50) | B14: ='Stress Tests'!$B$17 -> 1.8544633 | C14: =IF('Stress Tests'!$B$17>=Assumptions!$B$35,"Clears","BREACH") -> Clears | D14: No stress applied
A15: P90 production | B15: ='Stress Tests'!$B$29 -> 1.5911048 | C15: =IF('Stress Tests'!$B$29>=Assumptions!$B$35,"Clears","BREACH") -> Clears | D15: ~10% uncertainty on P50 wind yield
A16: Price shock (-20% ex-ante price) | B16: ='Stress Tests'!$B$41 -> 1.6833453 | C16: =IF('Stress Tests'!$B$41>=Assumptions!$B$35,"Clears","BREACH") -> Clears | D16: Pushes price toward/below the SDE+ floor
A17: Combined (P90 + price shock) | B17: ='Stress Tests'!$B$53 -> 1.4419165 | C17: =IF('Stress Tests'!$B$53>=Assumptions!$B$35,"Clears","BREACH") -> Clears | D17: Most severe scenario tested
A19: Benchmark: Gemini offshore wind (2014)
A20: Metric | B20: Gemini | C20: Borssele 1&2 | D20: Note
A21: Capacity (MW) | B21: 600 | C21: 752 | D21: Gemini ~20% smaller
A22: Financial close | B22: May 2014 | C22: Jul 2016 | D22: Gemini 2 years earlier, same cost-decline cycle
A23: Total project cost (EUR m) | B23: 2.8 | C23: 1.491 | D23: Gemini's cost reflects an earlier, higher-cost vintage
A24: Long-term debt facility (EUR m) | B24: 2.099 | C24: 920 (this model) | D24: Both financed via bank + ECA + EIB syndicate
A25: Implied gearing | B25: ~70% | C25: ~62% (LLCR-constrained) | D25: Gemini's a useful sense-check on syndicate scale
A26: Syndicate | B26: 22 parties incl. EIB, 1 pension fund | C26: EIB confirmed (EUR 500m) | D26: Confirms multi-lender syndication is standard at this scale
